Workbook

Sheet Roster Info
A1: Unique ID | B1: Artist name | C1: Preferred Name | D1: Preferred Pronouns | E1: Heritage | F1: Location | G1: Outside of UK (If applicable) | H1: Type of Act | I1: Genre | J1: Contact Details | K1: Instagram | L1: Soundcloud | M1: TikTok | N1: Any other social media | O1: Link to Previous Work | P1: Most Recent Date Booked | Q1: Event Name | R1: Small Gigs booked for | S1: Medium Gigs booked for | T1: Large Gigs booked for | U1: Gig Score (S =1, M =2 , L=3)
A2: 202 | B2: Zar | C2: Arun Dhanjal | D2: he/him | F2: London | H2: DJ, Live Act | I2: Multi genre | J2: adjzar@gmail.com | K2: https://linktr.ee/ajdzar | O2: https://www.mixcloud.com/NoBoundariesLDN_/zar-no-boundaries-guest-mix-001/ | P2: {=MAX(IF($A2='Booking Responses'!F:F,'Booking Responses'!D:D))} -> 45248 | Q2: {=INDEX('Booking Responses'!C:C,MATCH(1,('Booking Responses'!F:F=A2)*('Booking Responses'!D:D=P2),0))} -> Warehouse Project 2023 | R2: =COUNTIFS('Booking Responses'!F:F,"="&A2,'Booking Responses'!E:E,"Small*") -> 0 | S2: =COUNTIFS('Booking Responses'!F:F,"="&A2,'Booking Responses'!E:E,"Medium*") -> 2 | T2: =COUNTIFS('Booking Responses'!F:F,"="&A2,'Booking Responses'!E:E,"Large*") -> 3 | U2: =SUM((R2)+(S2*2)+(T2*3)) -> 13
A3: 203 | B3: Saadaan | C3: Saadaan Afghan | D3: He/Him | F3: London, Coventry | H3: DJ | I3: 140, Dubstep, Left Field Bass, 2-step/ukg, Hip Hop, Techno, Electro (sometimes House) | J3: saadko@outlook.com | K3: https://www.instagram.com/saadaan__________/ | O3: "saadaan.bandcamp.com waveplate.systems" | P3: {=MAX(IF($A3='Booking Responses'!F:F,'Booking Responses'!D:D))} -> 45044 | Q3: {=INDEX('Booking Responses'!C:C,MATCH(1,('Booking Responses'!F:F=A3)*('Booking Responses'!D:D=P3),0))} -> The Cause Free Party | R3: =COUNTIFS('Booking Responses'!F:F,"="&A3,'Booking Responses'!E:E,"Small*") -> 0 | S3: =COUNTIFS('Booking Responses'!F:F,"="&A3,'Booking Responses'!E:E,"Medium*") -> 2 | T3: =COUNTIFS('Booking Responses'!F:F,"="&A3,'Booking Responses'!E:E,"Large*") -> 0 | U3: =SUM((R3)+(S3*2)+(T3*3)) -> 4
A4: 205 | B4: Michael Diamond | C4: Michael Diamond | F4: London, Oxford | H4: DJ, Live Act | I4: Electronic, Jazz | J4: diamond.sounduk@gmail.com | K4: https://www.instagram.com/diamond.sound/ | L4: https://soundcloud.com/michaeldiamonduk | O4: https://linktr.ee/diamond.sound | P4: {=MAX(IF($A4='Booking Responses'!F:F,'Booking Responses'!D:D))} -> 45205 | Q4: {=INDEX('Booking Responses'!C:C,MATCH(1,('Booking Responses'!F:F=A4)*('Booking Responses'!D:D=P4),0))} -> Science Gallery London: Machine Mythologies Oct 2023 | R4: =COUNTIFS('Booking Responses'!F:F,"="&A4,'Booking Responses'!E:E,"Small*") -> 1 | S4: =COUNTIFS('Booking Responses'!F:F,"="&A4,'Booking Responses'!E:E,"Medium*") -> 0 | T4: =COUNTIFS('Booking Responses'!F:F,"="&A4,'Booking Responses'!E:E,"Large*") -> 0 | U4: =SUM((R4)+(S4*2)+(T4*3)) -> 1
A5: 206 | B5: Sita Shah | C5: Sita Shah | F5: London | H5: DJ | I5: Techno, Hardcore, Breaks, Desi, Bootlegs | J5: sitashahsworld@gmail.com | K5: https://www.instagram.com/shahmbles/ | L5: soundcloud.com/sitashahdj | O5: https://linktr.ee/Sitashah | P5: {=MAX(IF($A5='Booking Responses'!F:F,'Booking Responses'!D:D))} -> 45395 | Q5: {=INDEX('Booking Responses'!C:C,MATCH(1,('Booking Responses'!F:F=A5)*('Booking Responses'!D:D=P5),0))} -> DAYTIMERS BERLIN | R5: =COUNTIFS('Booking Responses'!F:F,"="&A5,'Booking Responses'!E:E,"Small*") -> 0 | S5: =COUNTIFS('Booking Responses'!F:F,"="&A5,'Booking Responses'!E:E,"Medium*") -> 4 | T5: =COUNTIFS('Booking Responses'!F:F,"="&A5,'Booking Responses'!E:E,"Large*") -> 2 | U5: =SUM((R5)+(S5*2)+(T5*3)) -> 14
A6: 207 | B6: Rainmann | C6: Ral Daryanani | F6: London | H6: DJ, Live Act | I6: Tech House, Rap, Hip Hop, Deep House, House | J6: rainmann@tuta.io | L6: https://soundcloud.com/rainm4nn | O6: https://linktr.ee/rainmann | P6: {=MAX(IF($A6='Booking Responses'!F:F,'Booking Responses'!D:D))} -> 0 | Q6: {=INDEX('Booking Responses'!C:C,MATCH(1,('Booking Responses'!F:F=A6)*('Booking Responses'!D:D=P6),0))} -> #N/A | R6: =COUNTIFS('Booking Responses'!F:F,"="&A6,'Booking Responses'!E:E,"Small*") -> 0 | S6: =COUNTIFS('Booking Responses'!F:F,"="&A6,'Booking Responses'!E:E,"Medium*") -> 0 | T6: =COUNTIFS('Booking Responses'!F:F,"="&A6,'Booking Responses'!E:E,"Large*") -> 0 | U6: =SUM((R6)+(S6*2)+(T6*3)) -> 0
A7: 208 | B7: Somatic | C7: Somin Griffin-Dave | F7: Bristol | H7: DJ | I7: DnB, Jungle, Breakbeat, Garage, IDM, Experimental, Various other 4x4 genres, (Classic) Afrobeat, a touch of bossa and various other things | J7: somin.somatic@gmail.com | K7: https://www.instagram.com/somin.somatic/ | L7: https://soundcloud.com/somingriffin-dave | O7: https://linktr.ee/somin_somatic | P7: {=MAX(IF($A7='Booking Responses'!F:F,'Booking Responses'!D:D))} -> 45178 | Q7: {=INDEX('Booking Responses'!C:C,MATCH(1,('Booking Responses'!F:F=A7)*('Booking Responses'!D:D=P7),0))} -> Panjabi MC x Apache Indian: Fox and Firkin 2023 | R7: =COUNTIFS('Booking Responses'!F:F,"="&A7,'Booking Responses'!E:E,"Small*") -> 0 | S7: =COUNTIFS('Booking Responses'!F:F,"="&A7,'Booking Responses'!E:E,"Medium*") -> 2 | T7: =COUNTIFS('Booking Responses'!F:F,"="&A7,'Booking Responses'!E:E,"Large*") -> 1 | U7: =SUM((R7)+(S7*2)+(T7*3)) -> 7
A8: 209 | B8: Freshta | C8: Freshta Ebrahim | F8: London | H8: DJ | I8: Grime, Dubstep, Leftfield Bass, Breaks, Hard Drum | J8: freshtainfo@gmail.com | K8: https://www.instagram.com/_freshta/ | L8: https://soundcloud.com/freshtadj | O8: http://linktr.ee/_freshta | P8: {=MAX(IF($A8='Booking Responses'!F:F,'Booking Responses'!D:D))} -> 45098 | Q8: {=INDEX('Booking Responses'!C:C,MATCH(1,('Booking Responses'!F:F=A8)*('Booking Responses'!D:D=P8),0))} -> Glasto 2023 | R8: =COUNTIFS('Booking Responses'!F:F,"="&A8,'Booking Responses'!E:E,"Small*") -> 0 | S8: =COUNTIFS('Booking Responses'!F:F,"="&A8,'Booking Responses'!E:E,"Medium*") -> 2 | T8: =COUNTIFS('Booking Responses'!F:F,"="&A8,'Booking Responses'!E:E,"Large*") -> 2 | U8: =SUM((R8)+(S8*2)+(T8*3)) -> 10
A9: 210 | B9: GoldTooth | C9: Jaedan Gowthaman | F9: London | H9: DJ | I9: "Grime, Dubstep, UK Funky, Garage, Drill, SA House, afrohouse, kuduro. Also specialise in vinyl sets. | J9: dj@goldtooth.uk | K9: https://www.instagram.com/_goldtooth_/ | L9: http://soundcloud.com/goldtooth_dj | O9: https://linktr.ee/DJGoldTooth | P9: {=MAX(IF($A9='Booking Responses'!F:F,'Booking Responses'!D:D))} -> 45149 | Q9: {=INDEX('Booking Responses'!C:C,MATCH(1,('Booking Responses'!F:F=A9)*('Booking Responses'!D:D=P9),0))} -> Dhaga Arts 2023 | R9: =COUNTIFS('Booking Responses'!F:F,"="&A9,'Booking Responses'!E:E,"Small*") -> 1 | S9: =COUNTIFS('Booking Responses'!F:F,"="&A9,'Booking Responses'!E:E,"Medium*") -> 2 | T9: =COUNTIFS('Booking Responses'!F:F,"="&A9,'Booking Responses'!E:E,"Large*") -> 1 | U9: =SUM((R9)+(S9*2)+(T9*3)) -> 8
A10: 211 | B10: Temujin | C10: Roop | F10: London | H10: DJ | I10: UK underground dance - Bass, Techno, Breaks, Garage, Jungle, Dubstep, Grime (heavy on the percs and dub) | J10: temujin.ldn@gmail.com | K10: https://www.instagram.com/temujin_ldn/ | L10: http://soundcloud.com/temujin-ldn | O10: https://www.flowcode.com/page/temujin.ldn | P10: {=MAX(IF($A10='Booking Responses'!F:F,'Booking Responses'!D:D))} -> 45395 | Q10: {=INDEX('Booking Responses'!C:C,MATCH(1,('Booking Responses'!F:F=A10)*('Booking Responses'!D:D=P10),0))} -> DAYTIMERS BERLIN | R10: =COUNTIFS('Booking Responses'!F:F,"="&A10,'Booking Responses'!E:E,"Small*") -> 0 | S10: =COUNTIFS('Booking Responses'!F:F,"="&A10,'Booking Responses'!E:E,"Medium*") -> 5 | T10: =COUNTIFS('Booking Responses'!F:F,"="&A10,'Booking Responses'!E:E,"Large*") -> 1 | U10: =SUM((R10)+(S10*2)+(T10*3)) -> 13
A11: 212 | B11: Saachi | C11: Saachi | F11: London | H11: DJ | I11: House (sometimes electro & Ghettotech) | J11: djsaachi@hotmail.com | K11: https://www.instagram.com/saachi_versaachi/ | L11: https://soundcloud.com/saachi-bains | O11: https://lnk.bio/Saachi | P11: {=MAX(IF($A11='Booking Responses'!F:F,'Booking Responses'!D:D))} -> 44413 | Q11: {=INDEX('Booking Responses'!C:C,MATCH(1,('Booking Responses'!F:F=A11)*('Booking Responses'!D:D=P11),0))} -> Boiler Room | R11: =COUNTIFS('Booking Responses'!F:F,"="&A11,'Booking Responses'!E:E,"Small*") -> 0 | S11: =COUNTIFS('Booking Responses'!F:F,"="&A11,'Booking Responses'!E:E,"Medium*") -> 1 | T11: =COUNTIFS('Booking Responses'!F:F,"="&A11,'Booking Responses'!E:E,"Large*") -> 2 | U11: =SUM((R11)+(S11*2)+(T11*3)) -> 8
A12: 213 | B12: Kishan | C12: Kishan Thakrar | F12: London | H12: DJ | I12: UKG, House, Hip Hop/Afrobeat, 140, Jungle, DnB etc | J12: music@kishan.co.uk | K12: https://www.instagram.com/kishanthakrar/ | L12: https://soundcloud.com/kishanthakrar | O12: https://www.liinks.co/kishan | P12: {=MAX(IF($A12='Booking Responses'!F:F,'Booking Responses'!D:D))} -> 44701 | Q12: {=INDEX('Booking Responses'!C:C,MATCH(1,('Booking Responses'!F:F=A12)*('Booking Responses'!D:D=P12),0))} -> Corsica Studios: 20/05/2022 | R12: =COUNTIFS('Booking Responses'!F:F,"="&A12,'Booking Responses'!E:E,"Small*") -> 0 | S12: =COUNTIFS('Booking Responses'!F:F,"="&A12,'Booking Responses'!E:E,"Medium*") -> 1 | T12: =COUNTIFS('Booking Responses'!F:F,"="&A12,'Booking Responses'!E:E,"Large*") -> 0 | U12: =SUM((R12)+(S12*2)+(T12*3)) -> 2
A13: 214 | B13: DJ PRIYA | C13: Priya Majhail | F13: London, Brighton | H13: DJ | I13: Reggaeton, Bashment, Dancehall, Funky | J13: majpri95@gmail.com | K13: https://www.instagram.com/deejaypri/ | L13: https://soundcloud.com/deejaypriya | O13: https://linktr.ee/Deejaypri | P13: {=MAX(IF($A13='Booking Responses'!F:F,'Booking Responses'!D:D))} -> 44646 | Q13: {=INDEX('Booking Responses'!C:C,MATCH(1,('Booking Responses'!F:F=A13)*('Booking Responses'!D:D=P13),0))} -> Rich Mix: London Remixed Festival | R13: =COUNTIFS('Booking Responses'!F:F,"="&A13,'Booking Responses'!E:E,"Small*") -> 0 | S13: =COUNTIFS('Booking Responses'!F:F,"="&A13,'Booking Responses'!E:E,"Medium*") -> 3 | T13: =COUNTIFS('Booking Responses'!F:F,"="&A13,'Booking Responses'!E:E,"Large*") -> 0 | U13: =SUM((R13)+(S13*2)+(T13*3)) -> 6
A14: 215 | B14: Qwirk | C14: Simaran Patel | F14: Manchester | H14: DJ | I14: Dubstep, Grime, Garage, Breakbeat, DnB, Footwork, Trap, Jungle | J14: qwirkdubstep@gmail.com | K14: https://www.instagram.com/qwirkbass/ | L14: https://soundcloud.com/qwirkk | M14: https://www.tiktok.com/@qwirkbass | O14: linktr.ee/qwirk | P14: {=MAX(IF($A14='Booking Responses'!F:F,'Booking Responses'!D:D))} -> 44805 | Q14: {=INDEX('Booking Responses'!C:C,MATCH(1,('Booking Responses'!F:F=A14)*('Booking Responses'!D:D=P14),0))} -> Ministry of Sound 2022 | R14: =COUNTIFS('Booking Responses'!F:F,"="&A14,'Booking Responses'!E:E,"Small*") -> 0 | S14: =COUNTIFS('Booking Responses'!F:F,"="&A14,'Booking Responses'!E:E,"Medium*") -> 1 | T14: =COUNTIFS('Booking Responses'!F:F,"="&A14,'Booking Responses'!E:E,"Large*") -> 0 | U14: =SUM((R14)+(S14*2)+(T14*3)) -> 2
A15: 216 | B15: Rohan Rakhit | C15: Rohan Rakhit | F15: London | H15: DJ | I15: Multi-genre | J15: rohan@daytimers.org | K15: https://www.instagram.com/rohan_rakhit/ | L15: https://soundcloud.com/rohan_rakhit | O15: https://linktr.ee/rohan.rakhit | P15: {=MAX(IF($A15='Booking Responses'!F:F,'Booking Responses'!D:D))} -> 45072 | Q15: {=INDEX('Booking Responses'!C:C,MATCH(1,('Booking Responses'!F:F=A15)*('Booking Responses'!D:D=P15),0))} -> Jazz Cafe | R15: =COUNTIFS('Booking Responses'!F:F,"="&A15,'Booking Responses'!E:E,"Small*") -> 1 | S15: =COUNTIFS('Booking Responses'!F:F,"="&A15,'Booking Responses'!E:E,"Medium*") -> 2 | T15: =COUNTIFS('Booking Responses'!F:F,"="&A15,'Booking Responses'!E:E,"Large*") -> 5 | U15: =SUM((R15)+(S15*2)+(T15*3)) -> 20
A16: 217 | B16: Jaskkkkkkk | C16: Jaskaran Notta | F16: Birmingham | H16: DJ | I16: Electro, Ghetto, Italo, breakbeat, chugg (sometimes garage, disco) | J16: jaskaran.notta97@gmail.com | K16: https://www.instagram.com/_jaskkkkkkk/ | L16: https://soundcloud.com/jaskkkkkkk?ref=clipboard&p=i&c=1&utm_source=clipboard&utm_medium=text&utm_campaign=social_sharing | O16: https://refugeworldwide.com/radio/daytimers-4th-feb-2022 | P16: {=MAX(IF($A16='Booking Responses'!F:F,'Booking Responses'!D:D))} -> 44763 | Q16: {=INDEX('Booking Responses'!C:C,MATCH(1,('Booking Responses'!F:F=A16)*('Booking Responses'!D:D=P16),0))} -> Secret Garden Party | R16: =COUNTIFS('Booking Responses'!F:F,"="&A16,'Booking Responses'!E:E,"Small*") -> 0 | S16: =COUNTIFS('Booking Responses'!F:F,"="&A16,'Booking Responses'!E:E,"Medium*") -> 0 | T16: =COUNTIFS('Booking Responses'!F:F,"="&A16,'Booking Responses'!E:E,"Large*") -> 1 | U16: =SUM((R16)+(S16*2)+(T16*3)) -> 3
A17: 218 | B17: King Monday | C17: Sherwyn Appadu | F17: London | H17: DJ, Live Act | I17: Pop, Psychedelic, Sega, UK Dance, Experimental, Electronic | J17: kxmonday@hotmail.com | K17: https://soundcloud.com/kingxmonday | L17: https://soundcloud.com/kingxmonday | O17: https://ffm.to/kingmonday | P17: {=MAX(IF($A17='Booking Responses'!F:F,'Booking Responses'!D:D))} -> 45189 | Q17: {=INDEX('Booking Responses'!C:C,MATCH(1,('Booking Responses'!F:F=A17)*('Booking Responses'!D:D=P17),0))} -> Mirrored Cosmos NOW Gallery 2023 | R17: =COUNTIFS('Booking Responses'!F:F,"="&A17,'Booking Responses'!E:E,"Small*") -> 2 | S17: =COUNTIFS('Booking Responses'!F:F,"="&A17,'Booking Responses'!E:E,"Medium*") -> 1 | T17: =COUNTIFS('Booking Responses'!F:F,"="&A17,'Booking Responses'!E:E,"Large*") -> 1 | U17: =SUM((R17)+(S17*2)+(T17*3)) -> 7
A18: 219 | B18: Mandle | C18: Debesh Mandal | F18: London, Manchester | H18: DJ | I18: House, Techno, Breaks, Jungle, Disco | J18: mandle.demain@gmail.com | L18: https://soundcloud.com/djmandle | O18: https://soundcloud.com/djmandle | P18: {=MAX(IF($A18='Booking Responses'!F:F,'Booking Responses'!D:D))} -> 0 | Q18: {=INDEX('Booking Responses'!C:C,MATCH(1,('Booking Responses'!F:F=A18)*('Booking Responses'!D:D=P18),0))} -> #N/A | R18: =COUNTIFS('Booking Responses'!F:F,"="&A18,'Booking Responses'!E:E,"Small*") -> 0 | S18: =COUNTIFS('Booking Responses'!F:F,"="&A18,'Booking Responses'!E:E,"Medium*") -> 0 | T18: =COUNTIFS('Booking Responses'!F:F,"="&A18,'Booking Responses'!E:E,"Large*") -> 0 | U18: =SUM((R18)+(S18*2)+(T18*3)) -> 0
A19: 220 | B19: manj | H19: DJ | J19: info@manj.uk | P19: {=MAX(IF($A19='Booking Responses'!F:F,'Booking Responses'!D:D))} -> 45178 | Q19: {=INDEX('Booking Responses'!C:C,MATCH(1,('Booking Responses'!F:F=A19)*('Booking Responses'!D:D=P19),0))} -> Panjabi MC x Apache Indian: Fox and Firkin 2023 | R19: =COUNTIFS('Booking Responses'!F:F,"="&A19,'Booking Responses'!E:E,"Small*") -> 0 | S19: =COUNTIFS('Booking Responses'!F:F,"="&A19,'Booking Responses'!E:E,"Medium*") -> 2 | T19: =COUNTIFS('Booking Responses'!F:F,"="&A19,'Booking Responses'!E:E,"Large*") -> 0 | U19: =SUM((R19)+(S19*2)+(T19*3)) -> 4
A20: 220 | B20: REA | C20: Rea Chawhan | F20: London, Bristol | G20: Madrid | H20: DJ | I20: Dnb, Breaks/Footwork, UKG, UK Dubstep | J20: reamusicuk@gmail.com | K20: https://www.instagram.com/reamusicuk/ | L20: https://soundcloud.com/readnb | O20: https://soundcloud.com/readnb | P20: {=MAX(IF($A20='Booking Responses'!F:F,'Booking Responses'!D:D))} -> 45178 | Q20: {=INDEX('Booking Responses'!C:C,MATCH(1,('Booking Responses'!F:F=A20)*('Booking Responses'!D:D=P20),0))} -> Panjabi MC x Apache Indian: Fox and Firkin 2023 | R20: =COUNTIFS('Booking Responses'!F:F,"="&A20,'Booking Responses'!E:E,"Small*") -> 0 | S20: =COUNTIFS('Booking Responses'!F:F,"="&A20,'Booking Responses'!E:E,"Medium*") -> 2 | T20: =COUNTIFS('Booking Responses'!F:F,"="&A20,'Booking Responses'!E:E,"Large*") -> 0 | U20: =SUM((R20)+(S20*2)+(T20*3)) -> 4
A21: 221 | B21: Sepoys | C21: Rohit Tandon | G21: Vancouver, Canada | H21: DJ | I21: Liquid DnB/ Jungle | J21: basspradesh@gmail.com | L21: https://soundcloud.com/sepoys | O21: https://soundcloud.com/sepoys | P21: {=MAX(IF($A21='Booking Responses'!F:F,'Booking Responses'!D:D))} -> 0 | Q21: {=INDEX('Booking Responses'!C:C,MATCH(1,('Booking Responses'!F:F=A21)*('Booking Responses'!D:D=P21),0))} -> #N/A | R21: =COUNTIFS('Booking Responses'!F:F,"="&A21,'Booking Responses'!E:E,"Small*") -> 0 | S21: =COUNTIFS('Booking Responses'!F:F,"="&A21,'Booking Responses'!E:E,"Medium*") -> 0 | T21: =COUNTIFS('Booking Responses'!F:F,"="&A21,'Booking Responses'!E:E,"Large*") -> 0 | U21: =SUM((R21)+(S21*2)+(T21*3)) -> 0
A22: 222 | B22: Provhat | C22: Provhat Rahman | F22: London | H22: DJ | I22: UK Bass | J22: provhat@daytimers.org | O22: - | P22: {=MAX(IF($A22='Booking Responses'!F:F,'Booking Responses'!D:D))} -> 45044 | Q22: {=INDEX('Booking Responses'!C:C,MATCH(1,('Booking Responses'!F:F=A22)*('Booking Responses'!D:D=P22),0))} -> Cause Free Party | R22: =COUNTIFS('Booking Responses'!F:F,"="&A22,'Booking Responses'!E:E,"Small*") -> 0 | S22: =COUNTIFS('Booking Responses'!F:F,"="&A22,'Booking Responses'!E:E,"Medium*") -> 5 | T22: =COUNTIFS('Booking Responses'!F:F,"="&A22,'Booking Responses'!E:E,"Large*") -> 0 | U22: =SUM((R22)+(S22*2)+(T22*3)) -> 10
A23: 223 | B23: Mera Bhai | C23: Kavhan Karthik | F23: London | H23: DJ, Live Act | I23: Detroit + Italo House + Disco, Acid House, Techno, Breaks, Funk, UKG, Global Riddims. Vinyl only sets include - strictly UKG, 70s-80s Bollywood disco, world/int'l psych/funk/disco | J23: merabhaiiimusic@gmail.com | O23: https://linktr.ee/merabhaiii | P23: {=MAX(IF($A23='Booking Responses'!F:F,'Booking Responses'!D:D))} -> 45164 | Q23: {=INDEX('Booking Responses'!C:C,MATCH(1,('Booking Responses'!F:F=A23)*('Booking Responses'!D:D=P23),0))} -> Lost Village Festival 2023 | R23: =COUNTIFS('Booking Responses'!F:F,"="&A23,'Booking Responses'!E:E,"Small*") -> 0 | S23: =COUNTIFS('Booking Responses'!F:F,"="&A23,'Booking Responses'!E:E,"Medium*") -> 4 | T23: =COUNTIFS('Booking Responses'!F:F,"="&A23,'Booking Responses'!E:E,"Large*") -> 3 | U23: =SUM((R23)+(S23*2)+(T23*3)) -> 17
A24: 224 | B24: Izzi | C24: Izzi Dickson | F24: London, Cambridge | H24: DJ | I24: UK bass, breaks, leftfield techno, hard drum, electro, jungle, footwork | J24: izzi.dickson@gmail.com | O24: https://soundcloud.app.goo.gl/aXWw6FdyUhNKSXZi6 | P24: {=MAX(IF($A24='Booking Responses'!F:F,'Booking Responses'!D:D))} -> 45163 | Q24: {=INDEX('Booking Responses'!C:C,MATCH(1,('Booking Responses'!F:F=A24)*('Booking Responses'!D:D=P24),0))} -> Phonox Residency August 2023 | R24: =COUNTIFS('Booking Responses'!F:F,"="&A24,'Booking Responses'!E:E,"Small*") -> 0 | S24: =COUNTIFS('Booking Responses'!F:F,"="&A24,'Booking Responses'!E:E,"Medium*") -> 2 | T24: =COUNTIFS('Booking Responses'!F:F,"="&A24,'Booking Responses'!E:E,"Large*") -> 0 | U24: =SUM((R24)+(S24*2)+(T24*3)) -> 4
A25: 226 | B25: Sunayah | C25: Sunayah Arshad | F25: London | H25: DJ | I25: house, amapiano, baile funk, uk funky, RnB | J25: sunayah.arshad@gmail.com | K25: https://www.instagram.com/sunayah._/?hl=en | L25: https://soundcloud.com/sunayah | O25: https://soundcloud.com/sunayah | P25: {=MAX(IF($A25='Booking Responses'!F:F,'Booking Responses'!D:D))} -> 44701 | Q25: {=INDEX('Booking Responses'!C:C,MATCH(1,('Booking Responses'!F:F=A25)*('Booking Responses'!D:D=P25),0))} -> Corsica Studios: 20/05/2022 | R25: =COUNTIFS('Booking Responses'!F:F,"="&A25,'Booking Responses'!E:E,"Small*") -> 0 | S25: =COUNTIFS('Booking Responses'!F:F,"="&A25,'Booking Responses'!E:E,"Medium*") -> 1 | T25: =COUNTIFS('Booking Responses'!F:F,"="&A25,'Booking Responses'!E:E,"Large*") -> 0 | U25: =SUM((R25)+(S25*2)+(T25*3)) -> 2
A26: 227 | B26: Triqi | C26: Iqra Nowshari | G26: Berlin, Germany | H26: DJ | I26: house, breaks, electro, techno, disco, soul, funk | J26: imadfromlove@gmail.com | K26: https://www.instagram.com/triqitrix/?hl=en | L26: https://soundcloud.com/triqi030 | O26: https://soundcloud.com/triqi030 | P26: {=MAX(IF($A26='Booking Responses'!F:F,'Booking Responses'!D:D))} -> 45395 | Q26: {=INDEX('Booking Responses'!C:C,MATCH(1,('Booking Responses'!F:F=A26)*('Booking Responses'!D:D=P26),0))} -> DAYTIMERS BERLIN | R26: =COUNTIFS('Booking Responses'!F:F,"="&A26,'Booking Responses'!E:E,"Small*") -> 0 | S26: =COUNTIFS('Booking Responses'!F:F,"="&A26,'Booking Responses'!E:E,"Medium*") -> 1 | T26: =COUNTIFS('Booking Responses'!F:F,"="&A26,'Booking Responses'!E:E,"Large*") -> 0 | U26: =SUM((R26)+(S26*2)+(T26*3)) -> 2
A27: 228 | B27: KRMA | C27: Kush Varma | G27: Los Angeles, USA | H27: DJ | I27: Electronic, trap, dnb, bass | J27: krmabeats@gmail.com | K27: https://www.instagram.com/krma.music/ | L27: https://soundcloud.com/krmabeats | N27: https://linktr.ee/krma.music | O27: https://soundcloud.com/krmabeats | P27: {=MAX(IF($A27='Booking Responses'!F:F,'Booking Responses'!D:D))} -> 0 | Q27: {=INDEX('Booking Responses'!C:C,MATCH(1,('Booking Responses'!F:F=A27)*('Booking Responses'!D:D=P27),0))} -> #N/A | R27: =COUNTIFS('Booking Responses'!F:F,"="&A27,'Booking Responses'!E:E,"Small*") -> 0 | S27: =COUNTIFS('Booking Responses'!F:F,"="&A27,'Booking Responses'!E:E,"Medium*") -> 0 | T27: =COUNTIFS('Booking Responses'!F:F,"="&A27,'Booking Responses'!E:E,"Large*") -> 0 | U27: =SUM((R27)+(S27*2)+(T27*3)) -> 0
A28: 229 | B28: Solar Plexus | C28: Rahul Dhulipala | F28: London, Cardiff, Swansea | H28: DJ | I28: ukg / uk dubstep / grime / breaks / 160 / jungle | K28: https://www.instagram.com/djsolarplexus/?hl=en-gb | L28: https://soundcloud.com/djsolarplexus?ref=clipboard&p=i&c=1&si=DA130D71E4104EB5BE04BC096A497BAF&utm_source=clipboard&utm_medium=text&utm_campaign=social_sharing | O28: https://soundcloud.com/djsolarplexus?ref=clipboard&p=i&c=1&si=DA130D71E4104EB5BE04BC096A497BAF&utm_source=clipboard&utm_medium=text&utm_campaign=social_sharing | P28: {=MAX(IF($A28='Booking Responses'!F:F,'Booking Responses'!D:D))} -> 0 | Q28: {=INDEX('Booking Responses'!C:C,MATCH(1,('Booking Responses'!F:F=A28)*('Booking Responses'!D:D=P28),0))} -> #N/A | R28: =COUNTIFS('Booking Responses'!F:F,"="&A28,'Booking Responses'!E:E,"Small*") -> 0 | S28: =COUNTIFS('Booking Responses'!F:F,"="&A28,'Booking Responses'!E:E,"Medium*") -> 0 | T28: =COUNTIFS('Booking Responses'!F:F,"="&A28,'Booking Responses'!E:E,"Large*") -> 0 | U28: =SUM((R28)+(S28*2)+(T28*3)) -> 0
A29: 230 | B29: Basra | C29: Harry Basra | F29: London | H29: DJ | I29: DnB | J29: Harrybasra1@gmail.com | L29: https://soundcloud.com/hazbro/tracks | O29: https://soundcloud.com/hazbro/tracks | P29: {=MAX(IF($A29='Booking Responses'!F:F,'Booking Responses'!D:D))} -> 0 | Q29: {=INDEX('Booking Responses'!C:C,MATCH(1,('Booking Responses'!F:F=A29)*('Booking Responses'!D:D=P29),0))} -> #N/A | R29: =COUNTIFS('Booking Responses'!F:F,"="&A29,'Booking Responses'!E:E,"Small*") -> 0 | S29: =COUNTIFS('Booking Responses'!F:F,"="&A29,'Booking Responses'!E:E,"Medium*") -> 0 | T29: =COUNTIFS('Booking Responses'!F:F,"="&A29,'Booking Responses'!E:E,"Large*") -> 0 | U29: =SUM((R29)+(S29*2)+(T29*3)) -> 0
A30: 231 | B30: G33 | C30: Gaia Ahuja | F30: London, Liverpool | H30: DJ | I30: UKG, UK funky, grime, bass, dancehall | J30: gaiaahuja7@hotmail.com | K30: www.instagram.com/gaia_ia/ | L30: https://soundcloud.com/gggeethreethree | O30: https://soundcloud.com/gggeethreethree/bbc-asian-network-pure-spice-guest-mix | P30: {=MAX(IF($A30='Booking Responses'!F:F,'Booking Responses'!D:D))} -> 45106 | Q30: {=INDEX('Booking Responses'!C:C,MATCH(1,('Booking Responses'!F:F=A30)*('Booking Responses'!D:D=P30),0))} -> MIF | R30: =COUNTIFS('Booking Responses'!F:F,"="&A30,'Booking Responses'!E:E,"Small*") -> 0 | S30: =COUNTIFS('Booking Responses'!F:F,"="&A30,'Booking Responses'!E:E,"Medium*") -> 2 | T30: =COUNTIFS('Booking Responses'!F:F,"="&A30,'Booking Responses'!E:E,"Large*") -> 1 | U30: =SUM((R30)+(S30*2)+(T30*3)) -> 7
A31: 232 | B31: Himay | C31: Himay | G31: Mumbai, India | H31: DJ | I31: House, Breaks, Electronic | J31: Himay.kumbhani89@gmail.com | K31: https://www.instagram.com/heeemay/ | L31: https://soundcloud.com/heeemay | O31: https://soundcloud.com/heeemay | P31: {=MAX(IF($A31='Booking Responses'!F:F,'Booking Responses'!D:D))} -> 0 | Q31: {=INDEX('Booking Responses'!C:C,MATCH(1,('Booking Responses'!F:F=A31)*('Booking Responses'!D:D=P31),0))} -> #N/A | R31: =COUNTIFS('Booking Responses'!F:F,"="&A31,'Booking Responses'!E:E,"Small*") -> 0 | S31: =COUNTIFS('Booking Responses'!F:F,"="&A31,'Booking Responses'!E:E,"Medium*") -> 0 | T31: =COUNTIFS('Booking Responses'!F:F,"="&A31,'Booking Responses'!E:E,"Large*") -> 0 | U31: =SUM((R31)+(S31*2)+(T31*3)) -> 0
A32: 233 | B32: Shortsell | C32: Apoorv Khanna | G32: Mumbai, India | H32: DJ | I32: Techno, Garage, Genre Agnostic | K32: https://www.instagram.com/shortsell.wav/ | L32: https://soundcloud.com/djshortsell | O32: https://www.mixcloud.com/djshortsell/ | P32: {=MAX(IF($A32='Booking Responses'!F:F,'Booking Responses'!D:D))} -> 0 | Q32: {=INDEX('Booking Responses'!C:C,MATCH(1,('Booking Responses'!F:F=A32)*('Booking Responses'!D:D=P32),0))} -> #N/A | R32: =COUNTIFS('Booking Responses'!F:F,"="&A32,'Booking Responses'!E:E,"Small*") -> 0 | S32: =COUNTIFS('Booking Responses'!F:F,"="&A32,'Booking Responses'!E:E,"Medium*") -> 0 | T32: =COUNTIFS('Booking Responses'!F:F,"="&A32,'Booking Responses'!E:E,"Large*") -> 0 | U32: =SUM((R32)+(S32*2)+(T32*3)) -> 0
A33: 234 | B33: IYRE | C33: Sasith Gamage | G33: Colombo, Sri Lanka | H33: DJ | I33: DnB | J33: leah@theboom.live | K33: https://www.instagram.com/iyre_dnb/ | L33: https://soundcloud.com/iyrednb | O33: https://linktr.ee/IYREdnb | P33: {=MAX(IF($A33='Booking Responses'!F:F,'Booking Responses'!D:D))} -> 0 | Q33: {=INDEX('Booking Responses'!C:C,MATCH(1,('Booking Responses'!F:F=A33)*('Booking Responses'!D:D=P33),0))} -> #N/A | R33: =COUNTIFS('Booking Responses'!F:F,"="&A33,'Booking Responses'!E:E,"Small*") -> 0 | S33: =COUNTIFS('Booking Responses'!F:F,"="&A33,'Booking Responses'!E:E,"Medium*") -> 0 | T33: =COUNTIFS('Booking Responses'!F:F,"="&A33,'Booking Responses'!E:E,"Large*") -> 0 | U33: =SUM((R33)+(S33*2)+(T33*3)) -> 0
A34: 235 | B34: Jayhaan | C34: Jehan Bhesania | G34: Mumbai, India | H34: DJ | I34: Asian Underground / Open Format / Jersey Club / Trap | J34: contactjayhan@gmail.com | K34: https://www.instagram.com/jayhaanofficial/ | L34: https://soundcloud.com/jayhaanofficial | O34: https://ghelo.biglink.to/jayhaan | P34: {=MAX(IF($A34='Booking Responses'!F:F,'Booking Responses'!D:D))} -> 0 | Q34: {=INDEX('Booking Responses'!C:C,MATCH(1,('Booking Responses'!F:F=A34)*('Booking Responses'!D:D=P34),0))} -> #N/A | R34: =COUNTIFS('Booking Responses'!F:F,"="&A34,'Booking Responses'!E:E,"Small*") -> 0 | S34: =COUNTIFS('Booking Responses'!F:F,"="&A34,'Booking Responses'!E:E,"Medium*") -> 0 | T34: =COUNTIFS('Booking Responses'!F:F,"="&A34,'Booking Responses'!E:E,"Large*") -> 0 | U34: =SUM((R34)+(S34*2)+(T34*3)) -> 0
A35: 236 | B35: Iti | C35: Itrat (Iti) Memon | G35: Brisbane, Australia | H35: DJ, Live Act | I35: UK Funky, Breaks, Electro, Garage, 2-step, ambient | J35: iti@affix.management | K35: https://www.instagram.com/iti______/ | L35: https://soundcloud.com/iti_mqn | O35: https://linktr.ee/iti_ | P35: {=MAX(IF($A35='Booking Responses'!F:F,'Booking Responses'!D:D))} -> 45163 | Q35: {=INDEX('Booking Responses'!C:C,MATCH(1,('Booking Responses'!F:F=A35)*('Booking Responses'!D:D=P35),0))} -> Phonox Residency August 2023 | R35: =COUNTIFS('Booking Responses'!F:F,"="&A35,'Booking Responses'!E:E,"Small*") -> 0 | S35: =COUNTIFS('Booking Responses'!F:F,"="&A35,'Booking Responses'!E:E,"Medium*") -> 1 | T35: =COUNTIFS('Booking Responses'!F:F,"="&A35,'Booking Responses'!E:E,"Large*") -> 0 | U35: =SUM((R35)+(S35*2)+(T35*3)) -> 2
A36: 237 | B36: Snad | C36: Shyam Anand | G36: Philadelphia, USA/Berlin, Germany | H36: DJ | I36: house, garage (New York, New Jersey and UK), good tech house | J36: snadbad@gmail.com | K36: https://www.instagram.com/snadmusic/ | L36: https://soundcloud.com/snad | O36: https://linktr.ee/snad | P36: {=MAX(IF($A36='Booking Responses'!F:F,'Booking Responses'!D:D))} -> 0 | Q36: {=INDEX('Booking Responses'!C:C,MATCH(1,('Booking Responses'!F:F=A36)*('Booking Responses'!D:D=P36),0))} -> #N/A | R36: =COUNTIFS('Booking Responses'!F:F,"="&A36,'Booking Responses'!E:E,"Small*") -> 0 | S36: =COUNTIFS('Booking Responses'!F:F,"="&A36,'Booking Responses'!E:E,"Medium*") -> 0 | T36: =COUNTIFS('Booking Responses'!F:F,"="&A36,'Booking Responses'!E:E,"Large*") -> 0 | U36: =SUM((R36)+(S36*2)+(T36*3)) -> 0
A37: 238 | B37: Gasing | C37: Akhilan Singam | F37: Bristol | H37: DJ | I37: House, Techno, Garage, Grime, Jungle | J37: akhilan2512@gmail.com | K37: www.instagram.com/gasingraised/ | L37: https://soundcloud.com/gasingraised | O37: https://www.mixcloud.com/gasingraised/ | P37: {=MAX(IF($A37='Booking Responses'!F:F,'Booking Responses'!D:D))} -> 0 | Q37: {=INDEX('Booking Responses'!C:C,MATCH(1,('Booking Responses'!F:F=A37)*('Booking Responses'!D:D=P37),0))} -> #N/A | R37: =COUNTIFS('Booking Responses'!F:F,"="&A37,'Booking Responses'!E:E,"Small*") -> 0 | S37: =COUNTIFS('Booking Responses'!F:F,"="&A37,'Booking Responses'!E:E,"Medium*") -> 0 | T37: =COUNTIFS('Booking Responses'!F:F,"="&A37,'Booking Responses'!E:E,"Large*") -> 0 | U37: =SUM((R37)+(S37*2)+(T37*3)) -> 0
A38: 239 | B38: Kai Kaspar | C38: Raj Chandrarajah | F38: Glasgow | H38: DJ | I38: House, electro & acid | O38: https://soundcloud.com/clydebuiltradio/kai-kasper-7221 | P38: {=MAX(IF($A38='Booking Responses'!F:F,'Booking Responses'!D:D))} -> 0 | Q38: {=INDEX('Booking Responses'!C:C,MATCH(1,('Booking Responses'!F:F=A38)*('Booking Responses'!D:D=P38),0))} -> #N/A | R38: =COUNTIFS('Booking Responses'!F:F,"="&A38,'Booking Responses'!E:E,"Small*") -> 0 | S38: =COUNTIFS('Booking Responses'!F:F,"="&A38,'Booking Responses'!E:E,"Medium*") -> 0 | T38: =COUNTIFS('Booking Responses'!F:F,"="&A38,'Booking Responses'!E:E,"Large*") -> 0 | U38: =SUM((R38)+(S38*2)+(T38*3)) -> 0
A39: 240 | B39: Full Motion Disaster | C39: Aniket Dabholkar | G39: Mumbai, India | H39: DJ | I39: Ghettotech, Breaks, Electro, House, Hard Dance | J39: fullmotiondisaster@gmail.com | K39: https://www.instagram.com/fullmotiondisaster/ | L39: https://soundcloud.com/full-motion-disaster | O39: https://soundcloud.com/full-motion-disaster | P39: {=MAX(IF($A39='Booking Responses'!F:F,'Booking Responses'!D:D))} -> 0 | Q39: {=INDEX('Booking Responses'!C:C,MATCH(1,('Booking Responses'!F:F=A39)*('Booking Responses'!D:D=P39),0))} -> #N/A | R39: =COUNTIFS('Booking Responses'!F:F,"="&A39,'Booking Responses'!E:E,"Small*") -> 0 | S39: =COUNTIFS('Booking Responses'!F:F,"="&A39,'Booking Responses'!E:E,"Medium*") -> 0 | T39: =COUNTIFS('Booking Responses'!F:F,"="&A39,'Booking Responses'!E:E,"Large*") -> 0 | U39: =SUM((R39)+(S39*2)+(T39*3)) -> 0
A40: 241 | B40: Cardamami | C40: Anisa Jackson | G40: New York, USA | H40: DJ | I40: All | J40: djcardamami@gmail.com | K40: https://www.instagram.com/djcardamami/ | L40: https://soundcloud.com/cardamami | O40: https://soundcloud.com/cardamami | P40: {=MAX(IF($A40='Booking Responses'!F:F,'Booking Responses'!D:D))} -> 45401 | Q40: {=INDEX('Booking Responses'!C:C,MATCH(1,('Booking Responses'!F:F=A40)*('Booking Responses'!D:D=P40),0))} -> Jazz Cafe | R40: =COUNTIFS('Booking Responses'!F:F,"="&A40,'Booking Responses'!E:E,"Small*") -> 0 | S40: =COUNTIFS('Booking Responses'!F:F,"="&A40,'Booking Responses'!E:E,"Medium*") -> 1 | T40: =COUNTIFS('Booking Responses'!F:F,"="&A40,'Booking Responses'!E:E,"Large*") -> 0 | U40: =SUM((R40)+(S40*2)+(T40*3)) -> 2
...

Sheet Stats
A1: Most Booked Artists (Overall) | B1: Top: | C1: 25
B2: Rank | C2: Artist name | D2: Preferred Name | E2: Preferred Pronouns | F2: Heritage | G2: Location | H2: Outside of UK (If applicable) | I2: Type of Act | J2: Genre | K2: Contact Details | L2: Instagram | M2: Soundcloud | N2: TikTok | O2: Any other social media | P2: Link to Previous Work | Q2: Most Recent Date Booked | R2: Event Name | S2: Small Gigs booked for | T2: Medium Gigs booked for | U2: Large Gigs booked for | V2: Gig Score (S =1, M =2 , L=3)
B3: {=iferror(rank(V3:V27, V3:V27, False), "")} -> 1 | C3: =IFERROR(__xludf.DUMMYFUNCTION("SORTN('Roster Info'!B44:U1000, C1, false, 'Roster Info'!U44:U1000, false)"),"Chande") -> Chande | I3: =IFERROR(__xludf.DUMMYFUNCTION("""COMPUTED_VALUE"""),"DJ") -> DJ | Q3: =IFERROR(__xludf.DUMMYFUNCTION("""COMPUTED_VALUE"""),45248.0) -> 45248 | R3: =IFERROR(__xludf.DUMMYFUNCTION("""COMPUTED_VALUE"""),"Warehouse Project 2023") -> Warehouse Project 2023 | S3: =IFERROR(__xludf.DUMMYFUNCTION("""COMPUTED_VALUE"""),2.0) -> 2 | T3: =IFERROR(__xludf.DUMMYFUNCTION("""COMPUTED_VALUE"""),4.0) -> 4 | U3: =IFERROR(__xludf.DUMMYFUNCTION("""COMPUTED_VALUE"""),5.0) -> 5 | V3: =IFERROR(__xludf.DUMMYFUNCTION("""COMPUTED_VALUE"""),25.0) -> 25
B4: 2 | C4: =IFERROR(__xludf.DUMMYFUNCTION("""COMPUTED_VALUE"""),"Nadī") -> Nadī | D4: =IFERROR(__xludf.DUMMYFUNCTION("""COMPUTED_VALUE"""),"Samia") -> Samia | G4: =IFERROR(__xludf.DUMMYFUNCTION("""COMPUTED_VALUE"""),"London") -> London | I4: =IFERROR(__xludf.DUMMYFUNCTION("""COMPUTED_VALUE"""),"DJ") -> DJ | J4: =IFERROR(__xludf.DUMMYFUNCTION("""COMPUTED_VALUE"""),"Club, dancehall, R&b, hiphop, Asian underground and more ") -> Club, dancehall, R&b, hiphop, Asian underground and more | K4: =IFERROR(__xludf.DUMMYFUNCTION("""COMPUTED_VALUE"""),"nadi.enquiries@gmail.com") -> nadi.enquiries@gmail.com | L4: =IFERROR(__xludf.DUMMYFUNCTION("""COMPUTED_VALUE"""),"https://www.instagram.com/nadi_bpm/") -> https://www.instagram.com/nadi_bpm/ | M4: =IFERROR(__xludf.DUMMYFUNCTION("""COMPUTED_VALUE"""),"https://soundcloud.com/thisisnadi") -> https://soundcloud.com/thisisnadi | P4: =IFERROR(__xludf.DUMMYFUNCTION("""COMPUTED_VALUE"""),"https://www.thisisnadi.com") -> https://www.thisisnadi.com | Q4: =IFERROR(__xludf.DUMMYFUNCTION("""COMPUTED_VALUE"""),45149.0) -> 45149 | R4: =IFERROR(__xludf.DUMMYFUNCTION("""COMPUTED_VALUE"""),"Phonox Residency August 2023") -> Phonox Residency August 2023 | S4: =IFERROR(__xludf.DUMMYFUNCTION("""COMPUTED_VALUE"""),4.0) -> 4 | T4: =IFERROR(__xludf.DUMMYFUNCTION("""COMPUTED_VALUE"""),4.0) -> 4 | U4: =IFERROR(__xludf.DUMMYFUNCTION("""COMPUTED_VALUE"""),2.0) -> 2 | V4: =IFERROR(__xludf.DUMMYFUNCTION("""COMPUTED_VALUE"""),18.0) -> 18
B5: 3 | C5: =IFERROR(__xludf.DUMMYFUNCTION("""COMPUTED_VALUE"""),"yourboykiran") -> yourboykiran | D5: =IFERROR(__xludf.DUMMYFUNCTION("""COMPUTED_VALUE"""),"Kiran Kotecha") -> Kiran Kotecha | G5: =IFERROR(__xludf.DUMMYFUNCTION("""COMPUTED_VALUE"""),"London") -> London | I5: =IFERROR(__xludf.DUMMYFUNCTION("""COMPUTED_VALUE"""),"DJ") -> DJ | J5: =IFERROR(__xludf.DUMMYFUNCTION("""COMPUTED_VALUE"""),"Flips + Edits / Baile Funk / UK Funky / Breaks / UKG / 140 / Electro / 160 / Jungle") -> Flips + Edits / Baile Funk / UK Funky / Breaks / UKG / 140 / Electro / 160 / Jungle | K5: =IFERROR(__xludf.DUMMYFUNCTION("""COMPUTED_VALUE"""),"yourboykiran@gmail.com") -> yourboykiran@gmail.com | L5: =IFERROR(__xludf.DUMMYFUNCTION("""COMPUTED_VALUE"""),"https://www.instagram.com/yourboykiran/") -> https://www.instagram.com/yourboykiran/ | M5: =IFERROR(__xludf.DUMMYFUNCTION("""COMPUTED_VALUE"""),"https://soundcloud.com/yourboykiran") -> https://soundcloud.com/yourboykiran | O5: =IFERROR(__xludf.DUMMYFUNCTION("""COMPUTED_VALUE"""),"https://lnk.bio/yourboykiran") -> https://lnk.bio/yourboykiran | P5: =IFERROR(__xludf.DUMMYFUNCTION("""COMPUTED_VALUE"""),"https://soundcloud.com/yourboykiran") -> https://soundcloud.com/yourboykiran | Q5: =IFERROR(__xludf.DUMMYFUNCTION("""COMPUTED_VALUE"""),45325.0) -> 45325 | R5: =IFERROR(__xludf.DUMMYFUNCTION("""COMPUTED_VALUE"""),"DT x NDR Versus") -> DT x NDR Versus | S5: =IFERROR(__xludf.DUMMYFUNCTION("""COMPUTED_VALUE"""),1.0) -> 1 | T5: =IFERROR(__xludf.DUMMYFUNCTION("""COMPUTED_VALUE"""),4.0) -> 4 | U5: =IFERROR(__xludf.DUMMYFUNCTION("""COMPUTED_VALUE"""),2.0) -> 2 | V5: =IFERROR(__xludf.DUMMYFUNCTION("""COMPUTED_VALUE"""),15.0) -> 15
B6: 4 | C6: =IFERROR(__xludf.DUMMYFUNCTION("""COMPUTED_VALUE"""),"Mahnoor") -> Mahnoor | I6: =IFERROR(__xludf.DUMMYFUNCTION("""COMPUTED_VALUE"""),"DJ") -> DJ | Q6: =IFERROR(__xludf.DUMMYFUNCTION("""COMPUTED_VALUE"""),45415.0) -> 45415 | R6: =IFERROR(__xludf.DUMMYFUNCTION("""COMPUTED_VALUE"""),"Liberation Squares Press Night") -> Liberation Squares Press Night | S6: =IFERROR(__xludf.DUMMYFUNCTION("""COMPUTED_VALUE"""),1.0) -> 1 | T6: =IFERROR(__xludf.DUMMYFUNCTION("""COMPUTED_VALUE"""),3.0) -> 3 | U6: =IFERROR(__xludf.DUMMYFUNCTION("""COMPUTED_VALUE"""),2.0) -> 2 | V6: =IFERROR(__xludf.DUMMYFUNCTION("""COMPUTED_VALUE"""),13.0) -> 13
B7: 5 | C7: =IFERROR(__xludf.DUMMYFUNCTION("""COMPUTED_VALUE"""),"amad.png") -> amad.png | D7: =IFERROR(__xludf.DUMMYFUNCTION("""COMPUTED_VALUE"""),"amad ilyas") -> amad ilyas | I7: =IFERROR(__xludf.DUMMYFUNCTION("""COMPUTED_VALUE"""),"DJ") -> DJ | Q7: =IFERROR(__xludf.DUMMYFUNCTION("""COMPUTED_VALUE"""),44806.0) -> 44806 | R7: =IFERROR(__xludf.DUMMYFUNCTION("""COMPUTED_VALUE"""),"Field Maneuvers 2022") -> Field Maneuvers 2022 | S7: =IFERROR(__xludf.DUMMYFUNCTION("""COMPUTED_VALUE"""),3.0) -> 3 | T7: =IFERROR(__xludf.DUMMYFUNCTION("""COMPUTED_VALUE"""),3.0) -> 3 | U7: =IFERROR(__xludf.DUMMYFUNCTION("""COMPUTED_VALUE"""),1.0) -> 1 | V7: =IFERROR(__xludf.DUMMYFUNCTION("""COMPUTED_VALUE"""),12.0) -> 12
B8: 6 | C8: =IFERROR(__xludf.DUMMYFUNCTION("""COMPUTED_VALUE"""),"Riva") -> Riva | I8: =IFERROR(__xludf.DUMMYFUNCTION("""COMPUTED_VALUE"""),"DJ") -> DJ | Q8: =IFERROR(__xludf.DUMMYFUNCTION("""COMPUTED_VALUE"""),44806.0) -> 44806 | R8: =IFERROR(__xludf.DUMMYFUNCTION("""COMPUTED_VALUE"""),"Field Maneuvers 2022") -> Field Maneuvers 2022 | S8: =IFERROR(__xludf.DUMMYFUNCTION("""COMPUTED_VALUE"""),0.0) -> 0 | T8: =IFERROR(__xludf.DUMMYFUNCTION("""COMPUTED_VALUE"""),4.0) -> 4 | U8: =IFERROR(__xludf.DUMMYFUNCTION("""COMPUTED_VALUE"""),1.0) -> 1 | V8: =IFERROR(__xludf.DUMMYFUNCTION("""COMPUTED_VALUE"""),11.0) -> 11
B9: 6 | C9: =IFERROR(__xludf.DUMMYFUNCTION("""COMPUTED_VALUE"""),"Vindya") -> Vindya | I9: =IFERROR(__xludf.DUMMYFUNCTION("""COMPUTED_VALUE"""),"DJ, Live Act") -> DJ, Live Act | Q9: =IFERROR(__xludf.DUMMYFUNCTION("""COMPUTED_VALUE"""),45106.0) -> 45106 | R9: =IFERROR(__xludf.DUMMYFUNCTION("""COMPUTED_VALUE"""),"MIF") -> MIF | S9: =IFERROR(__xludf.DUMMYFUNCTION("""COMPUTED_VALUE"""),0.0) -> 0 | T9: =IFERROR(__xludf.DUMMYFUNCTION("""COMPUTED_VALUE"""),4.0) -> 4 | U9: =IFERROR(__xludf.DUMMYFUNCTION("""COMPUTED_VALUE"""),1.0) -> 1 | V9: =IFERROR(__xludf.DUMMYFUNCTION("""COMPUTED_VALUE"""),11.0) -> 11
B10: 8 | C10: =IFERROR(__xludf.DUMMYFUNCTION("""COMPUTED_VALUE"""),"Anu") -> Anu | D10: =IFERROR(__xludf.DUMMYFUNCTION("""COMPUTED_VALUE"""),"Anu") -> Anu | I10: =IFERROR(__xludf.DUMMYFUNCTION("""COMPUTED_VALUE"""),"DJ") -> DJ | Q10: =IFERROR(__xludf.DUMMYFUNCTION("""COMPUTED_VALUE"""),44953.0) -> 44953 | R10: =IFERROR(__xludf.DUMMYFUNCTION("""COMPUTED_VALUE"""),"Watch the Drop ") -> Watch the Drop | S10: =IFERROR(__xludf.DUMMYFUNCTION("""COMPUTED_VALUE"""),1.0) -> 1 | T10: =IFERROR(__xludf.DUMMYFUNCTION("""COMPUTED_VALUE"""),3.0) -> 3 | U10: =IFERROR(__xludf.DUMMYFUNCTION("""COMPUTED_VALUE"""),1.0) -> 1 | V10: =IFERROR(__xludf.DUMMYFUNCTION("""COMPUTED_VALUE"""),10.0) -> 10
B11: 9 | C11: =IFERROR(__xludf.DUMMYFUNCTION("""COMPUTED_VALUE"""),"Raji Rags") -> Raji Rags | I11: =IFERROR(__xludf.DUMMYFUNCTION("""COMPUTED_VALUE"""),"DJ") -> DJ | Q11: =IFERROR(__xludf.DUMMYFUNCTION("""COMPUTED_VALUE"""),45044.0) -> 45044 | R11: =IFERROR(__xludf.DUMMYFUNCTION("""COMPUTED_VALUE"""),"The Cause Free Party") -> The Cause Free Party | S11: =IFERROR(__xludf.DUMMYFUNCTION("""COMPUTED_VALUE"""),0.0) -> 0 | T11: =IFERROR(__xludf.DUMMYFUNCTION("""COMPUTED_VALUE"""),3.0) -> 3 | U11: =IFERROR(__xludf.DUMMYFUNCTION("""COMPUTED_VALUE"""),1.0) -> 1 | V11: =IFERROR(__xludf.DUMMYFUNCTION("""COMPUTED_VALUE"""),9.0) -> 9
B12: 9 | C12: =IFERROR(__xludf.DUMMYFUNCTION("""COMPUTED_VALUE"""),"DJ Ritu") -> DJ Ritu | I12: =IFERROR(__xludf.DUMMYFUNCTION("""COMPUTED_VALUE"""),"DJ") -> DJ | Q12: =IFERROR(__xludf.DUMMYFUNCTION("""COMPUTED_VALUE"""),45122.0) -> 45122 | R12: =IFERROR(__xludf.DUMMYFUNCTION("""COMPUTED_VALUE"""),"HKW Berlin 2023") -> HKW Berlin 2023 | S12: =IFERROR(__xludf.DUMMYFUNCTION("""COMPUTED_VALUE"""),0.0) -> 0 | T12: =IFERROR(__xludf.DUMMYFUNCTION("""COMPUTED_VALUE"""),3.0) -> 3 | U12: =IFERROR(__xludf.DUMMYFUNCTION("""COMPUTED_VALUE"""),1.0) -> 1 | V12: =IFERROR(__xludf.DUMMYFUNCTION("""COMPUTED_VALUE"""),9.0) -> 9
B13: 9 | C13: =IFERROR(__xludf.DUMMYFUNCTION("""COMPUTED_VALUE"""),"Yung Singh") -> Yung Singh | I13: =IFERROR(__xludf.DUMMYFUNCTION("""COMPUTED_VALUE"""),"DJ") -> DJ | Q13: =IFERROR(__xludf.DUMMYFUNCTION("""COMPUTED_VALUE"""),44528.0) -> 44528 | R13: =IFERROR(__xludf.DUMMYFUNCTION("""COMPUTED_VALUE"""),"Jikoni: Samosa Sisterhood") -> Jikoni: Samosa Sisterhood | S13: =IFERROR(__xludf.DUMMYFUNCTION("""COMPUTED_VALUE"""),0.0) -> 0 | T13: =IFERROR(__xludf.DUMMYFUNCTION("""COMPUTED_VALUE"""),3.0) -> 3 | U13: =IFERROR(__xludf.DUMMYFUNCTION("""COMPUTED_VALUE"""),1.0) -> 1 | V13: =IFERROR(__xludf.DUMMYFUNCTION("""COMPUTED_VALUE"""),9.0) -> 9
B14: 12 | C14: =IFERROR(__xludf.DUMMYFUNCTION("""COMPUTED_VALUE"""),"Arthi") -> Arthi | D14: =IFERROR(__xludf.DUMMYFUNCTION("""COMPUTED_VALUE"""),"Arthi") -> Arthi | I14: =IFERROR(__xludf.DUMMYFUNCTION("""COMPUTED_VALUE"""),"DJ, Live Act") -> DJ, Live Act | Q14: =IFERROR(__xludf.DUMMYFUNCTION("""COMPUTED_VALUE"""),45072.0) -> 45072 | R14: =IFERROR(__xludf.DUMMYFUNCTION("""COMPUTED_VALUE"""),"Jazz Cafe ") -> Jazz Cafe | S14: =IFERROR(__xludf.DUMMYFUNCTION("""COMPUTED_VALUE"""),0.0) -> 0 | T14: =IFERROR(__xludf.DUMMYFUNCTION("""COMPUTED_VALUE"""),1.0) -> 1 | U14: =IFERROR(__xludf.DUMMYFUNCTION("""COMPUTED_VALUE"""),2.0) -> 2 | V14: =IFERROR(__xludf.DUMMYFUNCTION("""COMPUTED_VALUE"""),8.0) -> 8
B15: 12 | C15: =IFERROR(__xludf.DUMMYFUNCTION("""COMPUTED_VALUE"""),"Jameela") -> Jameela | I15: =IFERROR(__xludf.DUMMYFUNCTION("""COMPUTED_VALUE"""),"DJ") -> DJ | Q15: =IFERROR(__xludf.DUMMYFUNCTION("""COMPUTED_VALUE"""),45248.0) -> 45248 | R15: =IFERROR(__xludf.DUMMYFUNCTION("""COMPUTED_VALUE"""),"Warehouse Project 2023") -> Warehouse Project 2023 | S15: =IFERROR(__xludf.DUMMYFUNCTION("""COMPUTED_VALUE"""),0.0) -> 0 | T15: =IFERROR(__xludf.DUMMYFUNCTION("""COMPUTED_VALUE"""),1.0) -> 1 | U15: =IFERROR(__xludf.DUMMYFUNCTION("""COMPUTED_VALUE"""),2.0) -> 2 | V15: =IFERROR(__xludf.DUMMYFUNCTION("""COMPUTED_VALUE"""),8.0) -> 8
B16: 12 | C16: =IFERROR(__xludf.DUMMYFUNCTION("""COMPUTED_VALUE"""),"Khadura (fka Rizmi)") -> Khadura (fka Rizmi) | D16: =IFERROR(__xludf.DUMMYFUNCTION("""COMPUTED_VALUE"""),"Zoya") -> Zoya | G16: =IFERROR(__xludf.DUMMYFUNCTION("""COMPUTED_VALUE"""),"Birmingham") -> Birmingham | I16: =IFERROR(__xludf.DUMMYFUNCTION("""COMPUTED_VALUE"""),"DJ") -> DJ | K16: =IFERROR(__xludf.DUMMYFUNCTION("""COMPUTED_VALUE"""),"zoya.ahmed@live.co.uk") -> zoya.ahmed@live.co.uk | L16: =IFERROR(__xludf.DUMMYFUNCTION("""COMPUTED_VALUE"""),"https://www.instagram.com/khadura.sound?igsh=NGtmYXowbWYwZHp3") -> https://www.instagram.com/khadura.sound?igsh=NGtmYXowbWYwZHp3 | M16: =IFERROR(__xludf.DUMMYFUNCTION("""COMPUTED_VALUE"""),"https://soundcloud.com/khadura?utm_source=mobi&utm_campaign=social_sharing") -> https://soundcloud.com/khadura?utm_source=mobi&utm_campaign=social_sharing | Q16: =IFERROR(__xludf.DUMMYFUNCTION("""COMPUTED_VALUE"""),46107.0) -> 46107 | R16: =IFERROR(__xludf.DUMMYFUNCTION("""COMPUTED_VALUE"""),"BFI At Yours: Mogul Mowgli") -> BFI At Yours: Mogul Mowgli | S16: =IFERROR(__xludf.DUMMYFUNCTION("""COMPUTED_VALUE"""),2.0) -> 2 | T16: =IFERROR(__xludf.DUMMYFUNCTION("""COMPUTED_VALUE"""),0.0) -> 0 | U16: =IFERROR(__xludf.DUMMYFUNCTION("""COMPUTED_VALUE"""),2.0) -> 2 | V16: =IFERROR(__xludf.DUMMYFUNCTION("""COMPUTED_VALUE"""),8.0) -> 8
B17: 12 | C17: =IFERROR(__xludf.DUMMYFUNCTION("""COMPUTED_VALUE"""),"Shivum Sharma") -> Shivum Sharma | D17: =IFERROR(__xludf.DUMMYFUNCTION("""COMPUTED_VALUE"""),"Shivum Sharma") -> Shivum Sharma | I17: =IFERROR(__xludf.DUMMYFUNCTION("""COMPUTED_VALUE"""),"DJ, Live Act") -> DJ, Live Act | Q17: =IFERROR(__xludf.DUMMYFUNCTION("""COMPUTED_VALUE"""),44806.0) -> 44806 | R17: =IFERROR(__xludf.DUMMYFUNCTION("""COMPUTED_VALUE"""),"Field Maneuvers 2022") -> Field Maneuvers 2022 | S17: =IFERROR(__xludf.DUMMYFUNCTION("""COMPUTED_VALUE"""),0.0) -> 0 | T17: =IFERROR(__xludf.DUMMYFUNCTION("""COMPUTED_VALUE"""),4.0) -> 4 | U17: =IFERROR(__xludf.DUMMYFUNCTION("""COMPUTED_VALUE"""),0.0) -> 0 | V17: =IFERROR(__xludf.DUMMYFUNCTION("""COMPUTED_VALUE"""),8.0) -> 8
B18: 12 | C18: =IFERROR(__xludf.DUMMYFUNCTION("""COMPUTED_VALUE"""),"Thempress") -> Thempress | G18: =IFERROR(__xludf.DUMMYFUNCTION("""COMPUTED_VALUE"""),"London") -> London | I18: =IFERROR(__xludf.DUMMYFUNCTION("""COMPUTED_VALUE"""),"DJ") -> DJ | K18: =IFERROR(__xludf.DUMMYFUNCTION("""COMPUTED_VALUE"""),"N/A") -> N/A | Q18: =IFERROR(__xludf.DUMMYFUNCTION("""COMPUTED_VALUE"""),45120.0) -> 45120 | R18: =IFERROR(__xludf.DUMMYFUNCTION("""COMPUTED_VALUE"""),"Dour Fest") -> Dour Fest | S18: =IFERROR(__xludf.DUMMYFUNCTION("""COMPUTED_VALUE"""),0.0) -> 0 | T18: =IFERROR(__xludf.DUMMYFUNCTION("""COMPUTED_VALUE"""),1.0) -> 1 | U18: =IFERROR(__xludf.DUMMYFUNCTION("""COMPUTED_VALUE"""),2.0) -> 2 | V18: =IFERROR(__xludf.DUMMYFUNCTION("""COMPUTED_VALUE"""),8.0) -> 8
B19: 17 | C19: =IFERROR(__xludf.DUMMYFUNCTION("""COMPUTED_VALUE"""),"D-Lish") -> D-Lish | D19: =IFERROR(__xludf.DUMMYFUNCTION("""COMPUTED_VALUE"""),"Alisha Shah") -> Alisha Shah | I19: =IFERROR(__xludf.DUMMYFUNCTION("""COMPUTED_VALUE"""),"DJ") -> DJ | Q19: =IFERROR(__xludf.DUMMYFUNCTION("""COMPUTED_VALUE"""),45325.0) -> 45325 | R19: =IFERROR(__xludf.DUMMYFUNCTION("""COMPUTED_VALUE"""),"DT X NDR Versus") -> DT X NDR Versus | S19: =IFERROR(__xludf.DUMMYFUNCTION("""COMPUTED_VALUE"""),2.0) -> 2 | T19: =IFERROR(__xludf.DUMMYFUNCTION("""COMPUTED_VALUE"""),1.0) -> 1 | U19: =IFERROR(__xludf.DUMMYFUNCTION("""COMPUTED_VALUE"""),1.0) -> 1 | V19: =IFERROR(__xludf.DUMMYFUNCTION("""COMPUTED_VALUE"""),7.0) -> 7
B20: 17 | C20: =IFERROR(__xludf.DUMMYFUNCTION("""COMPUTED_VALUE"""),"Jhumka") -> Jhumka | I20: =IFERROR(__xludf.DUMMYFUNCTION("""COMPUTED_VALUE"""),"DJ") -> DJ | Q20: =IFERROR(__xludf.DUMMYFUNCTION("""COMPUTED_VALUE"""),45164.0) -> 45164 | R20: =IFERROR(__xludf.DUMMYFUNCTION("""COMPUTED_VALUE"""),"Lost Village Festival 2023") -> Lost Village Festival 2023 | S20: =IFERROR(__xludf.DUMMYFUNCTION("""COMPUTED_VALUE"""),0.0) -> 0 | T20: =IFERROR(__xludf.DUMMYFUNCTION("""COMPUTED_VALUE"""),2.0) -> 2 | U20: =IFERROR(__xludf.DUMMYFUNCTION("""COMPUTED_VALUE"""),1.0) -> 1 | V20: =IFERROR(__xludf.DUMMYFUNCTION("""COMPUTED_VALUE"""),7.0) -> 7
B21: 17 | C21: =IFERROR(__xludf.DUMMYFUNCTION("""COMPUTED_VALUE"""),"Aisha Mirza") -> Aisha Mirza | I21: =IFERROR(__xludf.DUMMYFUNCTION("""COMPUTED_VALUE"""),"DJ") -> DJ | Q21: =IFERROR(__xludf.DUMMYFUNCTION("""COMPUTED_VALUE"""),44972.0) -> 44972 | R21: =IFERROR(__xludf.DUMMYFUNCTION("""COMPUTED_VALUE"""),"HOR") -> HOR | S21: =IFERROR(__xludf.DUMMYFUNCTION("""COMPUTED_VALUE"""),1.0) -> 1 | T21: =IFERROR(__xludf.DUMMYFUNCTION("""COMPUTED_VALUE"""),0.0) -> 0 | U21: =IFERROR(__xludf.DUMMYFUNCTION("""COMPUTED_VALUE"""),2.0) -> 2 | V21: =IFERROR(__xludf.DUMMYFUNCTION("""COMPUTED_VALUE"""),7.0) -> 7
B22: 20 | C22: =IFERROR(__xludf.DUMMYFUNCTION("""COMPUTED_VALUE"""),"Suchi") -> Suchi | I22: =IFERROR(__xludf.DUMMYFUNCTION("""COMPUTED_VALUE"""),"DJ") -> DJ | Q22: =IFERROR(__xludf.DUMMYFUNCTION("""COMPUTED_VALUE"""),45098.0) -> 45098 | R22: =IFERROR(__xludf.DUMMYFUNCTION("""COMPUTED_VALUE"""),"Glasto 2023") -> Glasto 2023 | S22: =IFERROR(__xludf.DUMMYFUNCTION("""COMPUTED_VALUE"""),0.0) -> 0 | T22: =IFERROR(__xludf.DUMMYFUNCTION("""COMPUTED_VALUE"""),0.0) -> 0 | U22: =IFERROR(__xludf.DUMMYFUNCTION("""COMPUTED_VALUE"""),2.0) -> 2 | V22: =IFERROR(__xludf.DUMMYFUNCTION("""COMPUTED_VALUE"""),6.0) -> 6
B23: 20 | C23: =IFERROR(__xludf.DUMMYFUNCTION("""COMPUTED_VALUE"""),"Manara") -> Manara | I23: =IFERROR(__xludf.DUMMYFUNCTION("""COMPUTED_VALUE"""),"DJ") -> DJ | Q23: =IFERROR(__xludf.DUMMYFUNCTION("""COMPUTED_VALUE"""),44744.0) -> 44744 | R23: =IFERROR(__xludf.DUMMYFUNCTION("""COMPUTED_VALUE"""),"Daytimers x Middle Of Nowhere") -> Daytimers x Middle Of Nowhere | S23: =IFERROR(__xludf.DUMMYFUNCTION("""COMPUTED_VALUE"""),0.0) -> 0 | T23: =IFERROR(__xludf.DUMMYFUNCTION("""COMPUTED_VALUE"""),0.0) -> 0 | U23: =IFERROR(__xludf.DUMMYFUNCTION("""COMPUTED_VALUE"""),2.0) -> 2 | V23: =IFERROR(__xludf.DUMMYFUNCTION("""COMPUTED_VALUE"""),6.0) -> 6
B24: 20 | C24: =IFERROR(__xludf.DUMMYFUNCTION("""COMPUTED_VALUE"""),"DJ Rani") -> DJ Rani | I24: =IFERROR(__xludf.DUMMYFUNCTION("""COMPUTED_VALUE"""),"DJ") -> DJ | Q24: =IFERROR(__xludf.DUMMYFUNCTION("""COMPUTED_VALUE"""),44786.0) -> 44786 | R24: =IFERROR(__xludf.DUMMYFUNCTION("""COMPUTED_VALUE"""),"Boomtown: Street Stage Takeover") -> Boomtown: Street Stage Takeover | S24: =IFERROR(__xludf.DUMMYFUNCTION("""COMPUTED_VALUE"""),0.0) -> 0 | T24: =IFERROR(__xludf.DUMMYFUNCTION("""COMPUTED_VALUE"""),0.0) -> 0 | U24: =IFERROR(__xludf.DUMMYFUNCTION("""COMPUTED_VALUE"""),2.0) -> 2 | V24: =IFERROR(__xludf.DUMMYFUNCTION("""COMPUTED_VALUE"""),6.0) -> 6
B25: 20 | C25: =IFERROR(__xludf.DUMMYFUNCTION("""COMPUTED_VALUE"""),"SHIR.IN") -> SHIR.IN | I25: =IFERROR(__xludf.DUMMYFUNCTION("""COMPUTED_VALUE"""),"DJ") -> DJ | Q25: =IFERROR(__xludf.DUMMYFUNCTION("""COMPUTED_VALUE"""),45395.0) -> 45395 | R25: =IFERROR(__xludf.DUMMYFUNCTION("""COMPUTED_VALUE"""),"DAYTIMERS BERLIN") -> DAYTIMERS BERLIN | S25: =IFERROR(__xludf.DUMMYFUNCTION("""COMPUTED_VALUE"""),1.0) -> 1 | T25: =IFERROR(__xludf.DUMMYFUNCTION("""COMPUTED_VALUE"""),1.0) -> 1 | U25: =IFERROR(__xludf.DUMMYFUNCTION("""COMPUTED_VALUE"""),1.0) -> 1 | V25: =IFERROR(__xludf.DUMMYFUNCTION("""COMPUTED_VALUE"""),6.0) -> 6
B26: 20 | C26: =IFERROR(__xludf.DUMMYFUNCTION("""COMPUTED_VALUE"""),"Surusinghe") -> Surusinghe | I26: =IFERROR(__xludf.DUMMYFUNCTION("""COMPUTED_VALUE"""),"DJ") -> DJ | Q26: =IFERROR(__xludf.DUMMYFUNCTION("""COMPUTED_VALUE"""),45098.0) -> 45098 | R26: =IFERROR(__xludf.DUMMYFUNCTION("""COMPUTED_VALUE"""),"Glasto 2023") -> Glasto 2023 | S26: =IFERROR(__xludf.DUMMYFUNCTION("""COMPUTED_VALUE"""),0.0) -> 0 | T26: =IFERROR(__xludf.DUMMYFUNCTION("""COMPUTED_VALUE"""),0.0) -> 0 | U26: =IFERROR(__xludf.DUMMYFUNCTION("""COMPUTED_VALUE"""),2.0) -> 2 | V26: =IFERROR(__xludf.DUMMYFUNCTION("""COMPUTED_VALUE"""),6.0) -> 6
B27: 20 | C27: =IFERROR(__xludf.DUMMYFUNCTION("""COMPUTED_VALUE"""),"Zaleel") -> Zaleel | I27: =IFERROR(__xludf.DUMMYFUNCTION("""COMPUTED_VALUE"""),"DJ") -> DJ | Q27: =IFERROR(__xludf.DUMMYFUNCTION("""COMPUTED_VALUE"""),45262.0) -> 45262 | R27: =IFERROR(__xludf.DUMMYFUNCTION("""COMPUTED_VALUE"""),"Earth Hackney Dec 2023") -> Earth Hackney Dec 2023 | S27: =IFERROR(__xludf.DUMMYFUNCTION("""COMPUTED_VALUE"""),0.0) -> 0 | T27: =IFERROR(__xludf.DUMMYFUNCTION("""COMPUTED_VALUE"""),3.0) -> 3 | U27: =IFERROR(__xludf.DUMMYFUNCTION("""COMPUTED_VALUE"""),0.0) -> 0 | V27: =IFERROR(__xludf.DUMMYFUNCTION("""COMPUTED_VALUE"""),6.0) -> 6
A30: Most Recently Booked | B30: Top: | C30: 25
B31: Rank | C31: Artist name | D31: Preferred Name | E31: Preferred Pronouns | F31: Heritage | G31: Location | H31: Outside of UK (If applicable) | I31: Type of Act | J31: Genre | K31: Contact Details | L31: Instagram | M31: Soundcloud | N31: TikTok | O31: Any other social media | P31: Link to Previous Work | Q31: Most Recent Date Booked | R31: Event Name | S31: Small Gigs booked for | T31: Medium Gigs booked for | U31: Large Gigs booked for | V31: Gig Score (S =1, M =2 , L=3)
B32: {=iferror(rank(V32:V56, V32:V56, False), "")} -> 3 | C32: =IFERROR(__xludf.DUMMYFUNCTION("SORTN('Roster Info'!B44:U1000, C30, false, 'Roster Info'!P44:P1000, false)"),"Khadura (fka Rizmi)") -> Khadura (fka Rizmi) | D32: =IFERROR(__xludf.DUMMYFUNCTION("""COMPUTED_VALUE"""),"Zoya") -> Zoya | G32: =IFERROR(__xludf.DUMMYFUNCTION("""COMPUTED_VALUE"""),"Birmingham") -> Birmingham | I32: =IFERROR(__xludf.DUMMYFUNCTION("""COMPUTED_VALUE"""),"DJ") -> DJ | K32: =IFERROR(__xludf.DUMMYFUNCTION("""COMPUTED_VALUE"""),"zoya.ahmed@live.co.uk") -> zoya.ahmed@live.co.uk | L32: =IFERROR(__xludf.DUMMYFUNCTION("""COMPUTED_VALUE"""),"https://www.instagram.com/khadura.sound?igsh=NGtmYXowbWYwZHp3") -> https://www.instagram.com/khadura.sound?igsh=NGtmYXowbWYwZHp3 | M32: =IFERROR(__xludf.DUMMYFUNCTION("""COMPUTED_VALUE"""),"https://soundcloud.com/khadura?utm_source=mobi&utm_campaign=social_sharing") -> https://soundcloud.com/khadura?utm_source=mobi&utm_campaign=social_sharing | Q32: =IFERROR(__xludf.DUMMYFUNCTION("""COMPUTED_VALUE"""),46107.0) -> 46107 | R32: =IFERROR(__xludf.DUMMYFUNCTION("""COMPUTED_VALUE"""),"BFI At Yours: Mogul Mowgli") -> BFI At Yours: Mogul Mowgli | S32: =IFERROR(__xludf.DUMMYFUNCTION("""COMPUTED_VALUE"""),2.0) -> 2 | T32: =IFERROR(__xludf.DUMMYFUNCTION("""COMPUTED_VALUE"""),0.0) -> 0 | U32: =IFERROR(__xludf.DUMMYFUNCTION("""COMPUTED_VALUE"""),2.0) -> 2 | V32: =IFERROR(__xludf.DUMMYFUNCTION("""COMPUTED_VALUE"""),8.0) -> 8
B33: 7 | C33: =IFERROR(__xludf.DUMMYFUNCTION("""COMPUTED_VALUE"""),"Shifa Ligero") -> Shifa Ligero | G33: =IFERROR(__xludf.DUMMYFUNCTION("""COMPUTED_VALUE"""),"London") -> London | I33: =IFERROR(__xludf.DUMMYFUNCTION("""COMPUTED_VALUE"""),"DJ") -> DJ | J33: =IFERROR(__xludf.DUMMYFUNCTION("""COMPUTED_VALUE"""),"Dance, Amapiano, Jersey Club, Balie Funk, Rap, Edits") -> Dance, Amapiano, Jersey Club, Balie Funk, Rap, Edits | K33: =IFERROR(__xludf.DUMMYFUNCTION("""COMPUTED_VALUE"""),"shifaligero@gmail.com") -> shifaligero@gmail.com | L33: =IFERROR(__xludf.DUMMYFUNCTION("""COMPUTED_VALUE"""),"https://www.instagram.com/shifaligero/") -> https://www.instagram.com/shifaligero/ | M33: =IFERROR(__xludf.DUMMYFUNCTION("""COMPUTED_VALUE"""),"https://soundcloud.com/shifaligero") -> https://soundcloud.com/shifaligero | N33: =IFERROR(__xludf.DUMMYFUNCTION("""COMPUTED_VALUE"""),"https://www.tiktok.com/@shifaligero") -> https://www.tiktok.com/@shifaligero | Q33: =IFERROR(__xludf.DUMMYFUNCTION("""COMPUTED_VALUE"""),45630.0) -> 45630 | R33: =IFERROR(__xludf.DUMMYFUNCTION("""COMPUTED_VALUE"""),"Jazz Cafe ") -> Jazz Cafe | S33: =IFERROR(__xludf.DUMMYFUNCTION("""COMPUTED_VALUE"""),0.0) -> 0 | T33: =IFERROR(__xludf.DUMMYFUNCTION("""COMPUTED_VALUE"""),2.0) -> 2 | U33: =IFERROR(__xludf.DUMMYFUNCTION("""COMPUTED_VALUE"""),0.0) -> 0 | V33: =IFERROR(__xludf.DUMMYFUNCTION("""COMPUTED_VALUE"""),4.0) -> 4
B34: 12 | C34: =IFERROR(__xludf.DUMMYFUNCTION("""COMPUTED_VALUE"""),"Adnan.Afghani") -> Adnan.Afghani | D34: =IFERROR(__xludf.DUMMYFUNCTION("""COMPUTED_VALUE"""),"Adnan") -> Adnan | G34: =IFERROR(__xludf.DUMMYFUNCTION("""COMPUTED_VALUE"""),"London") -> London | I34: =IFERROR(__xludf.DUMMYFUNCTION("""COMPUTED_VALUE"""),"DJ") -> DJ | J34: =IFERROR(__xludf.DUMMYFUNCTION("""COMPUTED_VALUE"""),"""140/160 (techno/breaks/idm/dubstep) +experimental""") -> "140/160 (techno/breaks/idm/dubstep) +experimental" | K34: =IFERROR(__xludf.DUMMYFUNCTION("""COMPUTED_VALUE"""),"-") -> - | M34: =IFERROR(__xludf.DUMMYFUNCTION("""COMPUTED_VALUE"""),"https://soundcloud.com/daytimers_uk/adnan-afghani-disoriented-rhythms") -> https://soundcloud.com/daytimers_uk/adnan-afghani-disoriented-rhythms | P34: =IFERROR(__xludf.DUMMYFUNCTION("""COMPUTED_VALUE"""),"https://linktr.ee/adnan1198?fbclid=IwAR1RFFnK-rK7SohrsOqfXMyTqflU4LM_MhHgXmHq3o3qZ4QmW9sHmiT9kKk") -> https://linktr.ee/adnan1198?fbclid=IwAR1RFFnK-rK7SohrsOqfXMyTqflU4LM_MhHgXmHq3o3qZ4QmW9sHmiT9kKk | Q34: =IFERROR(__xludf.DUMMYFUNCTION("""COMPUTED_VALUE"""),45458.0) -> 45458 | R34: =IFERROR(__xludf.DUMMYFUNCTION("""COMPUTED_VALUE"""),"DAYTIMERS Festival") -> DAYTIMERS Festival | S34: =IFERROR(__xludf.DUMMYFUNCTION("""COMPUTED_VALUE"""),1.0) -> 1 | T34: =IFERROR(__xludf.DUMMYFUNCTION("""COMPUTED_VALUE"""),1.0) -> 1 | U34: =IFERROR(__xludf.DUMMYFUNCTION("""COMPUTED_VALUE"""),0.0) -> 0 | V34: =IFERROR(__xludf.DUMMYFUNCTION("""COMPUTED_VALUE"""),3.0) -> 3
B35: 14 | C35: =IFERROR(__xludf.DUMMYFUNCTION("""COMPUTED_VALUE"""),"Jawari") -> Jawari | D35: =IFERROR(__xludf.DUMMYFUNCTION("""COMPUTED_VALUE"""),"Jawari") -> Jawari | E35: =IFERROR(__xludf.DUMMYFUNCTION("""COMPUTED_VALUE"""),"they/them") -> they/them | F35: =IFERROR(__xludf.DUMMYFUNCTION("""COMPUTED_VALUE"""),"mixed") -> mixed | G35: =IFERROR(__xludf.DUMMYFUNCTION("""COMPUTED_VALUE"""),"London") -> London | I35: =IFERROR(__xludf.DUMMYFUNCTION("""COMPUTED_VALUE"""),"Live Act") -> Live Act | J35: =IFERROR(__xludf.DUMMYFUNCTION("""COMPUTED_VALUE"""),"Indo-Jazz") -> Indo-Jazz | K35: =IFERROR(__xludf.DUMMYFUNCTION("""COMPUTED_VALUE"""),"jawariband@gmail.com") -> jawariband@gmail.com | L35: =IFERROR(__xludf.DUMMYFUNCTION("""COMPUTED_VALUE"""),"https://www.instagram.com/jawariband/") -> https://www.instagram.com/jawariband/ | P35: =IFERROR(__xludf.DUMMYFUNCTION("""COMPUTED_VALUE"""),"https://open.spotify.com/artist/4dMY9QGjc6JqLcLvnzNWKH") -> https://open.spotify.com/artist/4dMY9QGjc6JqLcLvnzNWKH | Q35: =IFERROR(__xludf.DUMMYFUNCTION("""COMPUTED_VALUE"""),45458.0) -> 45458 | R35: =IFERROR(__xludf.DUMMYFUNCTION("""COMPUTED_VALUE"""),"DAYTIMERS Festival") -> DAYTIMERS Festival | S35: =IFERROR(__xludf.DUMMYFUNCTION("""COMPUTED_VALUE"""),0.0) -> 0 | T35: =IFERROR(__xludf.DUMMYFUNCTION("""COMPUTED_VALUE"""),1.0) -> 1 | U35: =IFERROR(__xludf.DUMMYFUNCTION("""COMPUTED_VALUE"""),0.0) -> 0 | V35: =IFERROR(__xludf.DUMMYFUNCTION("""COMPUTED_VALUE"""),2.0) -> 2
B36: 7 | C36: =IFERROR(__xludf.DUMMYFUNCTION("""COMPUTED_VALUE"""),"Sarith") -> Sarith | G36: =IFERROR(__xludf.DUMMYFUNCTION("""COMPUTED_VALUE"""),"London") -> London | I36: =IFERROR(__xludf.DUMMYFUNCTION("""COMPUTED_VALUE"""),"DJ") -> DJ | Q36: =IFERROR(__xludf.DUMMYFUNCTION("""COMPUTED_VALUE"""),45457.0) -> 45457 | R36: =IFERROR(__xludf.DUMMYFUNCTION("""COMPUTED_VALUE"""),"This Is Fine' by Poorna Bell") -> This Is Fine' by Poorna Bell | S36: =IFERROR(__xludf.DUMMYFUNCTION("""COMPUTED_VALUE"""),2.0) -> 2 | T36: =IFERROR(__xludf.DUMMYFUNCTION("""COMPUTED_VALUE"""),1.0) -> 1 | U36: =IFERROR(__xludf.DUMMYFUNCTION("""COMPUTED_VALUE"""),0.0) -> 0 | V36: =IFERROR(__xludf.DUMMYFUNCTION("""COMPUTED_VALUE"""),4.0) -> 4
B37: 2 | C37: =IFERROR(__xludf.DUMMYFUNCTION("""COMPUTED_VALUE"""),"Mahnoor") -> Mahnoor | I37: =IFERROR(__xludf.DUMMYFUNCTION("""COMPUTED_VALUE"""),"DJ") -> DJ | Q37: =IFERROR(__xludf.DUMMYFUNCTION("""COMPUTED_VALUE"""),45415.0) -> 45415 | R37: =IFERROR(__xludf.DUMMYFUNCTION("""COMPUTED_VALUE"""),"Liberation Squares Press Night") -> Liberation Squares Press Night | S37: =IFERROR(__xludf.DUMMYFUNCTION("""COMPUTED_VALUE"""),1.0) -> 1 | T37: =IFERROR(__xludf.DUMMYFUNCTION("""COMPUTED_VALUE"""),3.0) -> 3 | U37: =IFERROR(__xludf.DUMMYFUNCTION("""COMPUTED_VALUE"""),2.0) -> 2 | V37: =IFERROR(__xludf.DUMMYFUNCTION("""COMPUTED_VALUE"""),13.0) -> 13
B38: 7 | C38: =IFERROR(__xludf.DUMMYFUNCTION("""COMPUTED_VALUE"""),"Kirat") -> Kirat | G38: =IFERROR(__xludf.DUMMYFUNCTION("""COMPUTED_VALUE"""),"London") -> London | I38: =IFERROR(__xludf.DUMMYFUNCTION("""COMPUTED_VALUE"""),"DJ") -> DJ | K38: =IFERROR(__xludf.DUMMYFUNCTION("""COMPUTED_VALUE"""),"N/A") -> N/A | Q38: =IFERROR(__xludf.DUMMYFUNCTION("""COMPUTED_VALUE"""),45401.0) -> 45401 | R38: =IFERROR(__xludf.DUMMYFUNCTION("""COMPUTED_VALUE"""),"Jazz Cafe") -> Jazz Cafe | S38: =IFERROR(__xludf.DUMMYFUNCTION("""COMPUTED_VALUE"""),0.0) -> 0 | T38: =IFERROR(__xludf.DUMMYFUNCTION("""COMPUTED_VALUE"""),2.0) -> 2 | U38: =IFERROR(__xludf.DUMMYFUNCTION("""COMPUTED_VALUE"""),0.0) -> 0 | V38: =IFERROR(__xludf.DUMMYFUNCTION("""COMPUTED_VALUE"""),4.0) -> 4
B39: 12 | C39: =IFERROR(__xludf.DUMMYFUNCTION("""COMPUTED_VALUE"""),"Panjabi Hit Squad") -> Panjabi Hit Squad | G39: =IFERROR(__xludf.DUMMYFUNCTION("""COMPUTED_VALUE"""),"London") -> London | I39: =IFERROR(__xludf.DUMMYFUNCTION("""COMPUTED_VALUE"""),"DJ") -> DJ | J39: =IFERROR(__xludf.DUMMYFUNCTION("""COMPUTED_VALUE"""),"Garage") -> Garage | Q39: =IFERROR(__xludf.DUMMYFUNCTION("""COMPUTED_VALUE"""),45401.0) -> 45401 | R39: =IFERROR(__xludf.DUMMYFUNCTION("""COMPUTED_VALUE"""),"Jazz Cafe") -> Jazz Cafe | S39: =IFERROR(__xludf.DUMMYFUNCTION("""COMPUTED_VALUE"""),1.0) -> 1 | T39: =IFERROR(__xludf.DUMMYFUNCTION("""COMPUTED_VALUE"""),1.0) -> 1 | U39: =IFERROR(__xludf.DUMMYFUNCTION("""COMPUTED_VALUE"""),0.0) -> 0 | V39: =IFERROR(__xludf.DUMMYFUNCTION("""COMPUTED_VALUE"""),3.0) -> 3
